<?xml version="1.0"?>
<robot name="mira">
	<material name="blue">
		<color rgba="0 0 0.8 1"/>
	</material>
	<material name="red">
		<color rgba=" 0.8 0 0 1"/>
	</material>
	<material name="green">
		<color rgba="0 0.8 0 1"/>
	</material>
	<material name="grey">
		<color rgba=" 0.75 0.75 0.75 1"/>
	</material>
	<material name="white">
		<color rgba="1.0 1.0 1.0 1"/>
	</material>
	<material name="black">
		<color rgba=" 0 0 0 1"/>
	</material>


	<link name="base_link">
		<visual>
			<origin rpy = "0.0 0 0" xyz="0 0 0"/>
			<geometry>
				<cylinder radius="0.06" length="0.09"/>
			</geometry>
			<material name="grey"/>
		</visual>
	</link>

	<link name="roll_M1_link">

		<visual>
			<origin rpy="0 0 0" xyz="0 0 0"/>
			<geometry>
				<cylinder radius="0.06" length="0.09"/>
			</geometry>
			<material name="red"/>
		</visual>
	</link>

	<joint name="roll_joint" type="revolute">
		<parent link="base_link"/>
		<child link="roll_M1_link"/>
		<origin xyz = "0.0023 0 -0.005" rpy= "0 0 0"/>
		<limit lower= "-0.2" upper="0.2" effort="0.1" velocity="0.005"/>
		<axis xyz="1 0 0"/>
	</joint>

	<link name="pitch_M2_link">
		
		<visual>
			<origin rpy="0 0 0" xyz="0 0 0"/>
			<geometry>
				<cylinder radius="0.01" length="0.005"/>
			</geometry>
			<material name="green"/>
		</visual>
	</link>

	<joint name="pitch_joint" type="revolute">
		<parent link="roll_M1_link"/>
		<child link="pitch_M2_link"/>
		<origin xyz = "0 0 0" rpy= "0 -1.5708 0"/>
		<limit lower= "0" upper="0.44" effort="0.1" velocity="0.005"/>
		<axis xyz="0 1 0"/>
	</joint>
</robot>